<?xml version="1.0" ?>
<robot name="E05">
	<link name="link1">
		<visual>
			<geometry>
				<mesh filename="C:\Users\jan_s\Documents\Industrial Robotics\IRA2\IRA2\newcookedcode\meshes\E05_link1.dae" scale="0.01 0.01 0.01"/>
			</geometry>
			<origin rpy="1.5708 0 0"/>
		</visual>
		<collision>
			<geometry>
				<mesh filename="C:\Users\jan_s\Documents\Industrial Robotics\IRA2\IRA2\newcookedcode\meshes\E05_collision1.dae" scale="0.01 0.01 0.01"/>
			</geometry>
			<origin rpy="1.5708 0 0"/>
		</collision>
	</link>

	<link name="link2">
		<visual>
			<geometry>
				<mesh filename="C:\Users\jan_s\Documents\Industrial Robotics\IRA2\IRA2\newcookedcode\meshes\E05_link2.dae" scale="0.01 0.01 0.01"/>
			</geometry>
			<origin rpy="0 0 0" xyz="0 -0.4 0"/>
		</visual>
		<collision>
			<geometry>
				<mesh filename="C:\Users\jan_s\Documents\Industrial Robotics\IRA2\IRA2\newcookedcode\meshes\E05_collision2.dae" scale="0.01 0.01 0.01"/>
			</geometry>
			<origin rpy="0 0 0" xyz="0 -0.4 0"/>
		</collision>
	</link>

	<joint name="j1" type="revolute">
		<parent link="link1"/>
		<child link="link2"/>
		<origin rpy="1.570796325 0 0" xyz="0 0 0.54864"/>
		<axis xyz="0 1 0"/>
		<limit effort="1000.0" lower="-6.283185307" upper="6.283185307" velocity="0"/>
	</joint>

	<link name="link3">
		<visual>
			<geometry>
				<mesh filename="C:\Users\jan_s\Documents\Industrial Robotics\IRA2\IRA2\newcookedcode\meshes\E05_link3.dae" scale="0.01 0.01 0.01"/>
			</geometry>
			<origin rpy="0 0 0" xyz="-0.06 0.18 0"/>
		</visual>
		<collision>
			<geometry>
				<mesh filename="C:\Users\jan_s\Documents\Industrial Robotics\IRA2\IRA2\newcookedcode\meshes\E05_collision3.dae" scale="0.01 0.01 0.01"/>
			</geometry>
			<origin rpy="0 0 0" xyz="-0.06 0.18 0"/>
		</collision>
	</link>

	<joint name="j2" type="revolute">
		<parent link="link2"/>
		<child link="link3"/>
		<origin rpy="0 0 0" xyz="-0.06 -0.35 0"/>
		<axis xyz="1 0 0"/>
		<limit effort="1000.0" lower="-2.35619449" upper="2.35619449" velocity="0"/>
	</joint>

	<link name="link4">
		<visual>
			<geometry>
				<mesh filename="C:\Users\jan_s\Documents\Industrial Robotics\IRA2\IRA2\newcookedcode\meshes\E05_link4.dae" scale="0.01 0.01 0.01"/>
			</geometry>
			<origin rpy="0 0 0" xyz="0 0.07 0.0"/>
		</visual>
		<collision>
			<geometry>
				<mesh filename="C:\Users\jan_s\Documents\Industrial Robotics\IRA2\IRA2\newcookedcode\meshes\E05_collision4.dae" scale="0.01 0.01 0.01"/>
			</geometry>
			<origin rpy="0 0 0" xyz="0 0.07 0.0"/>
		</collision>
	</link>

	<joint name="j3" type="revolute">
		<parent link="link3"/>
		<child link="link4"/>
		<origin rpy="0 3.14159265 1.570796325" xyz="0.14 0.37 0.0"/>
		<axis xyz="0 1 0"/>
		<limit effort="1000.0" lower="-2.67035376" upper="2.67035376" velocity="0"/>
	</joint>

	<link name="link5">
		<visual>
			<geometry>
				<mesh filename="C:\Users\jan_s\Documents\Industrial Robotics\IRA2\IRA2\newcookedcode\meshes\E05_link5.dae" scale="0.01 0.01 0.01"/>
			</geometry>
			<origin rpy="0 0 1.57079632" xyz="0 0 0"/>
		</visual>
		<collision>
			<geometry>
				<mesh filename="C:\Users\jan_s\Documents\Industrial Robotics\IRA2\IRA2\newcookedcode\meshes\E05_collision5.dae" scale="0.01 0.01 0.01"/>
			</geometry>
			<origin rpy="0 0 1.57079632" xyz="0 0 0"/>
		</collision>
	</link>

	<joint name="j4" type="revolute">
		<parent link="link4"/>
		<child link="link5"/>
		<origin rpy="1.57079632 0 0" xyz="-0.25 0 0"/>
		<axis xyz="0 1 0"/>
		<limit effort="1000.0" lower="-6.283185307" upper="6.283185307" velocity="0"/>
	</joint>

	<link name="link6">
		<visual>
			<geometry>
				<mesh filename="C:\Users\jan_s\Documents\Industrial Robotics\IRA2\IRA2\newcookedcode\meshes\E05_link6.dae" scale="0.01 0.01 0.01"/>
			</geometry>
			<origin rpy="0 0 0" xyz="0 0 0.0"/>
		</visual>
		<collision>
			<geometry>
				<mesh filename="C:\Users\jan_s\Documents\Industrial Robotics\IRA2\IRA2\newcookedcode\meshes\E05_collision6.dae" scale="0.01 0.01 0.01"/>
			</geometry>
			<origin rpy="0 0 0" xyz="0 0 0.0"/>
		</collision>
	</link>

	<joint name="j5" type="revolute">
		<parent link="link5"/>
		<child link="link6"/>
		<origin rpy="1.570796325 0 1.570796325" xyz="-0.13 0 0.03"/>
		<axis xyz="0 0 1"/>
		<limit effort="1000.0" lower="-3.14159265" upper="3.14159265" velocity="0"/>
	</joint>

	<link name="link7">
		<visual>
			<geometry>
				<mesh filename="C:\Users\jan_s\Documents\Industrial Robotics\IRA2\IRA2\newcookedcode\meshes\E05_link7.dae" scale="0.01 0.01 0.01"/>
			</geometry>
			<origin rpy="0 0 0" xyz="0 0 0.0"/>
		</visual>
		<collision>
			<geometry>
				<cylinder length="0.01016" radius="0.0254"/>
			</geometry>
			<origin rpy="0 0 0" xyz="0 0 0.00508"/>
		</collision>
	</link>

	<joint name="j6" type="revolute">
		<parent link="link6"/>
		<child link="link7"/>
		<origin rpy="1.570796325 1.570796325 1.570796325" xyz="0 0.1 0"/>
		<axis xyz="0 0 1"/>
		<limit effort="1000.0" lower="-6.283185307" upper="6.283185307" velocity="0"/>
	</joint>
</robot>
